Workbook

Sheet Summary
A1: nodets-app: API endpoint inventory
A2: Built from the route definitions in the code on 4 October 2026 (branch rag-system, including uncommitted src/rag).
A3: REST paths are as served: routers under src/api are mounted at /v1. All run on one port (env PORT), with the WebSocket server.
A4: No endpoint requires authentication. Where a userId is taken, it is supplied by the caller.
A5: Input, response and error text comes from the Technical Specification Document, which was written by reading the code.
A6: Counts below are formulas over the "REST endpoints" sheet.
A8: Group | B8: GET | C8: POST | D8: PUT | E8: DELETE | F8: ANY | G8: Total
A9: Health check | B9: =COUNTIFS('REST endpoints'!$B$2:$B$99,$A9,'REST endpoints'!$C$2:$C$99,B$8) | C9: =COUNTIFS('REST endpoints'!$B$2:$B$99,$A9,'REST endpoints'!$C$2:$C$99,C$8) | D9: =COUNTIFS('REST endpoints'!$B$2:$B$99,$A9,'REST endpoints'!$C$2:$C$99,D$8) | E9: =COUNTIFS('REST endpoints'!$B$2:$B$99,$A9,'REST endpoints'!$C$2:$C$99,E$8) | F9: =COUNTIFS('REST endpoints'!$B$2:$B$99,$A9,'REST endpoints'!$C$2:$C$99,F$8) | G9: =SUM(B9:F9)
A10: Catalogue | B10: =COUNTIFS('REST endpoints'!$B$2:$B$99,$A10,'REST endpoints'!$C$2:$C$99,B$8) | C10: =COUNTIFS('REST endpoints'!$B$2:$B$99,$A10,'REST endpoints'!$C$2:$C$99,C$8) | D10: =COUNTIFS('REST endpoints'!$B$2:$B$99,$A10,'REST endpoints'!$C$2:$C$99,D$8) | E10: =COUNTIFS('REST endpoints'!$B$2:$B$99,$A10,'REST endpoints'!$C$2:$C$99,E$8) | F10: =COUNTIFS('REST endpoints'!$B$2:$B$99,$A10,'REST endpoints'!$C$2:$C$99,F$8) | G10: =SUM(B10:F10)
A11: Redis key/value | B11: =COUNTIFS('REST endpoints'!$B$2:$B$99,$A11,'REST endpoints'!$C$2:$C$99,B$8) | C11: =COUNTIFS('REST endpoints'!$B$2:$B$99,$A11,'REST endpoints'!$C$2:$C$99,C$8) | D11: =COUNTIFS('REST endpoints'!$B$2:$B$99,$A11,'REST endpoints'!$C$2:$C$99,D$8) | E11: =COUNTIFS('REST endpoints'!$B$2:$B$99,$A11,'REST endpoints'!$C$2:$C$99,E$8) | F11: =COUNTIFS('REST endpoints'!$B$2:$B$99,$A11,'REST endpoints'!$C$2:$C$99,F$8) | G11: =SUM(B11:F11)
A12: Kafka | B12: =COUNTIFS('REST endpoints'!$B$2:$B$99,$A12,'REST endpoints'!$C$2:$C$99,B$8) | C12: =COUNTIFS('REST endpoints'!$B$2:$B$99,$A12,'REST endpoints'!$C$2:$C$99,C$8) | D12: =COUNTIFS('REST endpoints'!$B$2:$B$99,$A12,'REST endpoints'!$C$2:$C$99,D$8) | E12: =COUNTIFS('REST endpoints'!$B$2:$B$99,$A12,'REST endpoints'!$C$2:$C$99,E$8) | F12: =COUNTIFS('REST endpoints'!$B$2:$B$99,$A12,'REST endpoints'!$C$2:$C$99,F$8) | G12: =SUM(B12:F12)
A13: File storage: local disk | B13: =COUNTIFS('REST endpoints'!$B$2:$B$99,$A13,'REST endpoints'!$C$2:$C$99,B$8) | C13: =COUNTIFS('REST endpoints'!$B$2:$B$99,$A13,'REST endpoints'!$C$2:$C$99,C$8) | D13: =COUNTIFS('REST endpoints'!$B$2:$B$99,$A13,'REST endpoints'!$C$2:$C$99,D$8) | E13: =COUNTIFS('REST endpoints'!$B$2:$B$99,$A13,'REST endpoints'!$C$2:$C$99,E$8) | F13: =COUNTIFS('REST endpoints'!$B$2:$B$99,$A13,'REST endpoints'!$C$2:$C$99,F$8) | G13: =SUM(B13:F13)
A14: File storage: fs-util | B14: =COUNTIFS('REST endpoints'!$B$2:$B$99,$A14,'REST endpoints'!$C$2:$C$99,B$8) | C14: =COUNTIFS('REST endpoints'!$B$2:$B$99,$A14,'REST endpoints'!$C$2:$C$99,C$8) | D14: =COUNTIFS('REST endpoints'!$B$2:$B$99,$A14,'REST endpoints'!$C$2:$C$99,D$8) | E14: =COUNTIFS('REST endpoints'!$B$2:$B$99,$A14,'REST endpoints'!$C$2:$C$99,E$8) | F14: =COUNTIFS('REST endpoints'!$B$2:$B$99,$A14,'REST endpoints'!$C$2:$C$99,F$8) | G14: =SUM(B14:F14)
A15: File storage: MinIO | B15: =COUNTIFS('REST endpoints'!$B$2:$B$99,$A15,'REST endpoints'!$C$2:$C$99,B$8) | C15: =COUNTIFS('REST endpoints'!$B$2:$B$99,$A15,'REST endpoints'!$C$2:$C$99,C$8) | D15: =COUNTIFS('REST endpoints'!$B$2:$B$99,$A15,'REST endpoints'!$C$2:$C$99,D$8) | E15: =COUNTIFS('REST endpoints'!$B$2:$B$99,$A15,'REST endpoints'!$C$2:$C$99,E$8) | F15: =COUNTIFS('REST endpoints'!$B$2:$B$99,$A15,'REST endpoints'!$C$2:$C$99,F$8) | G15: =SUM(B15:F15)
A16: Task planner | B16: =COUNTIFS('REST endpoints'!$B$2:$B$99,$A16,'REST endpoints'!$C$2:$C$99,B$8) | C16: =COUNTIFS('REST endpoints'!$B$2:$B$99,$A16,'REST endpoints'!$C$2:$C$99,C$8) | D16: =COUNTIFS('REST endpoints'!$B$2:$B$99,$A16,'REST endpoints'!$C$2:$C$99,D$8) | E16: =COUNTIFS('REST endpoints'!$B$2:$B$99,$A16,'REST endpoints'!$C$2:$C$99,E$8) | F16: =COUNTIFS('REST endpoints'!$B$2:$B$99,$A16,'REST endpoints'!$C$2:$C$99,F$8) | G16: =SUM(B16:F16)
A17: Settings | B17: =COUNTIFS('REST endpoints'!$B$2:$B$99,$A17,'REST endpoints'!$C$2:$C$99,B$8) | C17: =COUNTIFS('REST endpoints'!$B$2:$B$99,$A17,'REST endpoints'!$C$2:$C$99,C$8) | D17: =COUNTIFS('REST endpoints'!$B$2:$B$99,$A17,'REST endpoints'!$C$2:$C$99,D$8) | E17: =COUNTIFS('REST endpoints'!$B$2:$B$99,$A17,'REST endpoints'!$C$2:$C$99,E$8) | F17: =COUNTIFS('REST endpoints'!$B$2:$B$99,$A17,'REST endpoints'!$C$2:$C$99,F$8) | G17: =SUM(B17:F17)
A18: Goals | B18: =COUNTIFS('REST endpoints'!$B$2:$B$99,$A18,'REST endpoints'!$C$2:$C$99,B$8) | C18: =COUNTIFS('REST endpoints'!$B$2:$B$99,$A18,'REST endpoints'!$C$2:$C$99,C$8) | D18: =COUNTIFS('REST endpoints'!$B$2:$B$99,$A18,'REST endpoints'!$C$2:$C$99,D$8) | E18: =COUNTIFS('REST endpoints'!$B$2:$B$99,$A18,'REST endpoints'!$C$2:$C$99,E$8) | F18: =COUNTIFS('REST endpoints'!$B$2:$B$99,$A18,'REST endpoints'!$C$2:$C$99,F$8) | G18: =SUM(B18:F18)
A19: Chat (REST) | B19: =COUNTIFS('REST endpoints'!$B$2:$B$99,$A19,'REST endpoints'!$C$2:$C$99,B$8) | C19: =COUNTIFS('REST endpoints'!$B$2:$B$99,$A19,'REST endpoints'!$C$2:$C$99,C$8) | D19: =COUNTIFS('REST endpoints'!$B$2:$B$99,$A19,'REST endpoints'!$C$2:$C$99,D$8) | E19: =COUNTIFS('REST endpoints'!$B$2:$B$99,$A19,'REST endpoints'!$C$2:$C$99,E$8) | F19: =COUNTIFS('REST endpoints'!$B$2:$B$99,$A19,'REST endpoints'!$C$2:$C$99,F$8) | G19: =SUM(B19:F19)
A20: AI providers | B20: =COUNTIFS('REST endpoints'!$B$2:$B$99,$A20,'REST endpoints'!$C$2:$C$99,B$8) | C20: =COUNTIFS('REST endpoints'!$B$2:$B$99,$A20,'REST endpoints'!$C$2:$C$99,C$8) | D20: =COUNTIFS('REST endpoints'!$B$2:$B$99,$A20,'REST endpoints'!$C$2:$C$99,D$8) | E20: =COUNTIFS('REST endpoints'!$B$2:$B$99,$A20,'REST endpoints'!$C$2:$C$99,E$8) | F20: =COUNTIFS('REST endpoints'!$B$2:$B$99,$A20,'REST endpoints'!$C$2:$C$99,F$8) | G20: =SUM(B20:F20)
... A29: Pages and docs | B29: =COUNTIFS('REST endpoints'!$B$2:$B$99,$A29,'REST endpoints'!$C$2:$C$99,B$8) | C29: =COUNTIFS('REST endpoints'!$B$2:$B$99,$A29,'REST endpoints'!$C$2:$C$99,C$8) | D29: =COUNTIFS('REST endpoints'!$B$2:$B$99,$A29,'REST endpoints'!$C$2:$C$99,D$8) | E29: =COUNTIFS('REST endpoints'!$B$2:$B$99,$A29,'REST endpoints'!$C$2:$C$99,E$8) | F29: =COUNTIFS('REST endpoints'!$B$2:$B$99,$A29,'REST endpoints'!$C$2:$C$99,F$8) | G29: =SUM(B29:F29)
A30: Total | B30: =SUM(B9:B29) | C30: =SUM(C9:C29) | D30: =SUM(D9:D29) | E30: =SUM(E9:E29) | F30: =SUM(F9:F29) | G30: =SUM(G9:G29)
A32: WebSocket paths | B32: 3 | C32: /ws/server, /ws/stream, /ws/chatAI (see the WebSocket sheet)

Sheet REST endpoints
A1: # | B1: Group | C1: Method | D1: Path | E1: Input | F1: Success response | G1: Notable errors | H1: Source (file:line)
A2: 1 | B2: Health check | C2: GET | D2: /v1/health-check | E2: None | F2: 200, Service is healthy | G2: None | H2: src/api/healthCheck/healthCheckRouter.ts:23
A3: 2 | B3: Health check | C3: GET | D3: /v1/health-check/db | E3: None | F3: 200, MongoDB connection successful | G3: 503, MongoDB connection failed: <reason> | H3: src/api/healthCheck/healthCheckRouter.ts:35
A4: 3 | B4: Catalogue | C4: GET | D4: /v1/catalogue | E4: Query id | F4: Upstream status; one product | G4: 404; 500 Error finding catalogue with id <n>:, ... | H4: src/api/catalogue/catalogueRouter.ts:24
A5: 4 | B5: Catalogue | C5: POST | D5: /v1/catalogue | E5: { id, name, category?, stock?, price?, description? } | F5: 201; the whole in-memory array | G5: 400 invalid body | H5: src/api/catalogue/catalogueRouter.ts:63
A6: 5 | B6: Catalogue | C6: DELETE | D6: /v1/catalogue/:id | E6: Positive numeric id | F6: 202; true | G6: 400; 404 when the id is not in the array | H6: src/api/catalogue/catalogueRouter.ts:90
A7: 6 | B7: Catalogue | C7: GET | D7: /v1/catalogue/:id | E7: Positive numeric id | F7: As above | G7: 400 invalid id; 404; 500 | H7: src/api/catalogue/catalogueRouter.ts:43
A8: 7 | B8: Catalogue | C8: DELETE | D8: /v1/catalogue/all | E8: None | F8: 202; true | G8: 404 when the array is already empty | H8: src/api/catalogue/catalogueRouter.ts:77
A9: 8 | B9: Redis key/value | C9: DELETE | D9: /v1/redis/:key | E9: None | F9: 200; number of keys deleted | G9: 404 Data not found; 500 | H9: src/api/redis/redisRouter.ts:59
A10: 9 | B10: Redis key/value | C10: GET | D10: /v1/redis/:key | E10: None | F10: 200; stored JSON | G10: 404 Data not found; 500 | H10: src/api/redis/redisRouter.ts:45
A11: 10 | B11: Redis key/value | C11: POST | D11: /v1/redis/:key | E11: Body with numeric id; the whole body is stored | F11: 200; OK | G11: 400 missing id; 500 Cannot add data into redis:, ... | H11: src/api/redis/redisRouter.ts:31
A12: 11 | B12: Redis key/value | C12: PUT | D12: /v1/redis/:key | E12: Body with numeric id | F12: 200; shallow merge into the stored value, written without a TTL | G12: 400; 500 | H12: src/api/redis/redisRouter.ts:80
A13: 12 | B13: Kafka | C13: POST | D13: /v1/kafka/postMessage | E13: { config: { topic, ... }, data: { ... } } | F13: 200; the producer's send result | G13: 400 missing config or data; 500 Unable to send message, <reason> (the expected result while Kafka is disabled) | H13: src/api/kafka/kafkaRouter.ts:44
... A58: 57 | B58: Chat (REST) | C58: POST | D58: /v1/ai/chat | E58: JSON: messages (array of { role, content }) or prompt; optional provider, model, temperature (0 to 2) | F58: 200 with { reply, reasoning?, model, provider, usage? } | G58: 400 validation (Provide either "messages" or "prompt".); 400 all messages blank; 500 provider failure | H58: src/api/chat/chatRouter.ts:29
A59: 58 | B59: AI providers | C59: GET | D59: /chatModels | E59: Optional provider query | F59: { models: [{ value, label }] } | H59: src/server.ts:142
A60: 59 | B60: AI providers | C60: GET | D60: /v1/aiProviders | E60: none | F60: [{ name, baseURL }] for every registered provider | H60: src/api/aiProviders/aiProvidersRouter.ts:33
A61: 60 | B61: AI utilities | C61: DELETE | D61: /v1/aiUtils/chat-history/:userId | E61: Session id | F61: { cleared: true }; deletes the Mongo document and the Redis usage key | H61: src/api/aiUtils/aiUtilsRouter.ts:127
A62: 61 | B62: AI utilities | C62: GET | D62: /v1/aiUtils/chat-history/:userId | E62: Session id | F62: User-role messages only, newest first | H62: src/api/aiUtils/aiUtilsRouter.ts:113
A63: 62 | B63: AI utilities | C63: GET | D63: /v1/aiUtils/loaded-models | E63: none | F63: [{ model }] from LocalAI GET /system | H63: src/api/aiUtils/aiUtilsRouter.ts:165
A64: 63 | B64: AI utilities | C64: POST | D64: /v1/aiUtils/text-to-speech | E64: { text, voice? } | F64: { audio: <base64 MP3>, contentType: 'audio/mpeg' }; model tts-1, default voice alloy, default provider | H64: src/api/aiUtils/aiUtilsRouter.ts:200
A65: 64 | B65: AI utilities | C65: GET | D65: /v1/aiUtils/token-usage/:userId | E65: Session id | F65: { prompt_tokens, completion_tokens, total_tokens } from Redis, zeros if absent | H65: src/api/aiUtils/aiUtilsRouter.ts:133
A66: 65 | B66: AI utilities | C66: GET | D66: /v1/aiUtils/total-token-usage | E66: Optional sessionId query | F66: That session's usage, or the sum over all token_usage_* keys | H66: src/api/aiUtils/aiUtilsRouter.ts:147
A67: 66 | B67: AI utilities | C67: POST | D67: /v1/aiUtils/unload-model | E67: { model } | F67: { model, success, message } via LocalAI POST /backend/shutdown | H67: src/api/aiUtils/aiUtilsRouter.ts:182
A68: 67 | B68: AI utilities | C68: POST | D68: /v1/aiUtils/unload-models | E68: none | F68: { unloaded, failed, results }; runs docker model list --openai then docker model unload <model> per model; 500 if any fails | H68: src/api/aiUtils/aiUtilsRouter.ts:153
A69: 68 | B69: Vision | C69: POST | D69: /v1/vision/analyze | E69: multipart/form-data: image (image MIME type, max 5 MB), optional prompt, provider, model | F69: 200 with { details, rawText, reasoning? } | G69: 400 no file; 400 non-image upload; 413 file over 5 MB; 500 provider failure | H69: src/api/vision/visionRouter.ts:54
A70: 69 | B70: Nutrition | C70: GET | D70: /v1/nutrition | E70: none | F70: Renders src/public/nutrition.ejs with an empty report | G70: none | H70: src/api/vision/nutritionRouter.ts:70
A71: 70 | B71: Nutrition | C71: POST | D71: /v1/nutrition | E71: Same multipart form (image, prompt) | F71: Renders the page with a nutrition report | G71: Page rendered with an error message | H71: src/api/vision/nutritionRouter.ts:74
A72: 71 | B72: Laya ticket triage | C72: POST | D72: /v1/laya/classify-ticket | E72: JSON: subject, body, optional questions (record of choice, score or noul question definitions) | F72: 200 with { answers, usage: { input_tokens, output_tokens } } | G72: 400 validation; 500 Failed to classify ticket: ... | H72: src/api/laya/router.ts:30
A73: 72 | B73: AI monitoring | C73: GET | D73: /v1/monitor/dashboard | E73: None | F73: Renders src/public/monitor.ejs with a relaxed Content-Security-Policy for this page | H73: src/api/monitor/monitorRouter.ts:22
A74: 73 | B74: AI monitoring | C74: GET | D74: /v1/monitor/logs | E74: None | F74: Up to 500 call logs, newest first | H74: src/api/monitor/monitorRouter.ts:35
A75: 74 | B75: AI monitoring | C75: GET | D75: /v1/monitor/models | E75: None | F75: Live LocalAI snapshot: loaded models from /system, per-model requests and tokens parsed from the Prometheus text at /metrics, process memory, CPU and uptime; reachable: false with zeros when LocalAI cannot be read | H75: src/api/monitor/monitorRouter.ts:43
A76: 75 | B76: AI monitoring | C76: GET | D76: /v1/monitor/stats | E76: None | F76: All persisted model stats with avgDurationMs | H76: src/api/monitor/monitorRouter.ts:58
A77: 76 | B77: AI monitoring | C77: GET | D77: /v1/monitor/stats/:model | E77: None | F77: One model's stats; 404 Stats not found | H77: src/api/monitor/monitorRouter.ts:65
A78: 77 | B78: RAG: Chroma | C78: DELETE | D78: /v1/rag | E78: none | F78: true (collection deleted) | H78: src/api/rag/ragRouter.ts:103
A79: 78 | B79: RAG: Chroma | C79: DELETE | D79: /v1/rag/file/:id | E79: none | F79: { removed } | H79: src/api/rag/ragRouter.ts:91
A80: 79 | B80: RAG: Chroma | C80: POST | D80: /v1/rag/ingest | E80: JSON source, optional fileId, bucket, url, content, provider, force | F80: 201 { count } (chunks indexed) | H80: src/api/rag/ragRouter.ts:59
A81: 80 | B81: RAG: Chroma | C81: GET | D81: /v1/rag/search | E81: q (required), k 1-20 (default 3) | F81: { results: [{ id, text, score }] } | H81: src/api/rag/ragRouter.ts:74
A82: 81 | B82: RAG: Chroma | C82: GET | D82: /v1/rag/stats | E82: none | F82: { count, collections } | H82: src/api/rag/ragRouter.ts:115
A83: 82 | B83: RAG: Chroma | C83: POST | D83: /v1/rag/test-embed | E83: text, optional provider | F83: 201 { id } | H83: src/api/rag/ragRouter.ts:54
A84: 83 | B84: RAG: LlamaIndex | C84: DELETE | D84: /v1/llamaIndex | E84: none | F84: true (drops the whole collection) | H84: src/api/llamaIndex/router.ts:185
...

Sheet WebSocket
A1: WebSocket path | B1: Kind | C1: Method / message type | D1: Fields | E1: Result / when sent | F1: Source
A2: /ws/server | B2: RPC method | C2: ping | D2: none | E2: 'pong', wrapped as { type: 'response', id, result } | F2: src/ws/server/handlers/ping.ts
A3: /ws/server | B3: RPC method | C3: getTime | D3: none | E3: { time: <ISO string> } | F3: src/ws/server/handlers/getTime.ts
A4: /ws/server | B4: RPC method | C4: getUser | D4: userId (top level of the message) | E4: { id: userId, name: 'John Doe' } (stub) | F4: src/ws/server/handlers/getUsers.ts
A5: /ws/stream | B5: RPC method | C5: stream | D5: params.n (default 5) | E5: stream_start, then n stream_chunk frames, then stream_end | F5: src/ws/server/handlers/stream.ts
A6: /ws/stream | B6: RPC method | C6: openai | D6: params.prompt, model, stream | E6: stream_start, stream_continue frames with aiResponse.content, then stream_end or stream_error | F6: src/ws/server/handlers/openai.ts
A7: /ws/chatAI | B7: Client message | C7: chat turn | D7: id (session), model, provider, stream, rag, userId (required when rag is true), ragMinScore, params.prompt, params.imageIds / params.imageId, params.fileIds | E7: See the server messages below | F7: src/ws/server/handlers/chatbot/index.ts
A8: /ws/chatAI | B8: Client message | C8: stop_stream | D8: type: 'stop_stream', id (session) | E8: stream_stopped | F8: src/ws/server/handlers/chatbot/index.ts
A9: /ws/chatAI | B9: Server message | C9: stream_start | D9: id, historyCompacted, requestStartTime, ragSources | E9: Sent after history, attachments and RAG are prepared | F9: src/ws/server/handlers/chatbot/
A10: /ws/chatAI | B10: Server message | C10: stream_continue | D10: aiResponse (streaming: the delta; non-streaming: the whole message, with id) | E10: Sent for each content chunk, or once | F10: src/ws/server/handlers/chatbot/
A11: /ws/chatAI | B11: Server message | C11: stream_end | D11: id, tokenUsage, ragSources, requestStartTime, requestEndTime | E11: Normal completion | F11: src/ws/server/handlers/chatbot/
A12: /ws/chatAI | B12: Server message | C12: stream_stopped | D12: id, plus timing and usage fields when available | E12: Request aborted, or stop_stream with nothing active | F12: src/ws/server/handlers/chatbot/
... A14: any other path | B14: Server message | C14: error | D14: none | E14: { type: 'error', error: 'Unknown URL: <url>' } | F14: src/ws/server/index.ts
